Workbook

Sheet RECAPITULATIF
A1: 📋 RÉCAPITULATIF — ORDRE DES OPÉRATIONS DANS EXCEL
A3: Ordre | B3: Action | C3: Feuille Excel | D3: Section mémoire | E3: Statut
A4: 1 | B4: Insertion des données brutes non filtrées | C4: DONNEES BRUTES non filtrées | D4: — | E4: ✅ Automatisé
A5: 2 | B5: Vérifier les 2 filtres appliqués (Q1≠Jamais, Q29=Neutre) et concerne l'audit | C5: DONNEES_SOURCE | D5: 4.3.2 | E5: ✅ Automatisé
A6: 3 | B6: Variables inversées Q11_inv, Q22_inv, Q25_inv, Q26_inv, Q8_norm | C6: 0_PREPARATION | D6: 4.2.1 | E6: ✅ Calculé
A7: 4 | B7: 5 scores composites (SUP, SFU, SRP, SMF, SS) | C7: 0_PREPARATION | D7: 4.2.1 | E7: ✅ Calculé
A8: 5 | B8: Regroupement Q33 → Q33_groupe (3 niveaux) | C8: 0_PREPARATION | D8: 5.1 | E8: ✅ Calculé
A9: 6 | B9: Tableaux de fréquences Q31→Q36 + graphiques | C9: 5.1_PROFIL_ECHANTILLON | D9: 5.1 | E9: ✅ Calculé
A10: 7 | B10: Statistiques descriptives des 5 scores + Q1 + Q30 | C10: 5.2_STATS_DESC_CRONBACH | D10: 5.2 | E10: ✅ Calculé
A11: 8 | B11: Alpha de Cronbach pour les 5 scores (×5) | C11: 5.2_STATS_DESC_CRONBACH | D11: 5.2 | E11: ✅ Calculé
A12: 9 | B12: Corrélations Spearman H1, H2, H3, H4a, H4b | C12: 5.3_TEST_HYPOTHESES | D12: 5.3 | E12: ✅ Calculé
A13: 10 | B13: Régressions OLS (H1+H2 conjointe, H4b) | C13: 5.3_TEST_HYPOTHESES | D13: 5.3 | E13: ✅ Calculé
A14: 11 | B14: Sous-groupes Q19 pour H4a (formés vs peu formés) | C14: 5.3_TEST_HYPOTHESES | D14: 5.3 | E14: ✅ Calculé
A15: 12 | B15: Kruskal-Wallis + Mann-Whitney (grade, cabinet) | C15: 5.4_ANALYSES_COMPLEM | D15: 5.4 | E15: ✅ Calculé
... A17: 14 | B17: Rédiger la discussion à partir des guides | C17: 5.5_GUIDE_DISCUSSION | D17: 5.5 | E17: 📝 À rédiger
B20: 📊 FEUILLES D'HYPOTHÈSES CRÉÉES
A21: Ordre | B21: Action | C21: Feuille Excel | D21: Section mémoire | E21: Statut
A22: 15 | B22: Test H1 : SUP → Q1 (Utilité perçue → Usage) - Spearman détaillé par items Q6/Q7 | C22: H1_SUP_Q1 | D22: 5.3 | E22: ✅ Calculé
A23: 16 | B23: Test H2 : SFU → Q1 (Facilité d'usage → Usage) - Spearman + composantes Q9/Q10/Q11 | C23: H2_SFU_Q1 | D23: 5.3 | E23: ✅ Calculé
A24: 17 | B24: Test H3 : SRP → Q17/Q1 (Risques perçus → Frein/Usage) - H3a et H3a-2 | C24: H3_SRP | D24: 5.3 | E24: ✅ Calculé
A25: 18 | B25: Test H4a : Modération SMF sur SRP → Q1 (Terciles compétence) | C25: H4a_MODERATION | D25: 5.3 | E25: ✅ Calculé
A26: 19 | B26: Test H4b : Scepticisme et biais d'automatisation | C26: H4b_SCEPTICISME | D26: 5.3 | E26: ✅ Calculé
B28: 📈 RÉSUMÉ DES RÉSULTATS DES HYPOTHÈSES
A29: Hypothèse | B29: Test | C29: ρ Spearman | D29: p-value | E29: Verdict
A30: H1: SUP → Q1 | B30: Spearman | C30: ='5.3_HYPOTHESES'!C21 -> 0.16799573 | D30: ='5.3_HYPOTHESES'!D21 -> 0.17417627 | E30: INFIRMÉE (globalement)
A31: H2: SFU → Q1 | B31: Spearman | C31: =H2_SFU_Q1!C29 -> 0.32492787 | D31: =H2_SFU_Q1!F29 -> 0.0073005317 | E31: CONFIRMÉE *
A32: H3a: SRP → Q17 | B32: Spearman | C32: =H3_SRP!C32 -> 0.30950561 | D32: =H3_SRP!F32 -> 0.010814038 | E32: CONFIRMÉE *
A33: H3a-2: SRP → Q1 | B33: Spearman | C33: =H3_SRP!C33 -> -0.23098832 | D33: =H3_SRP!F33 -> 0.060018257 | E33: CONFIRMÉE *
A34: H4a: Modération | B34: Gradient terciles | C34: =CONCATENATE(ROUND(H4a_MODERATION!D25,2)," → ",ROUND(H4a_MODERATION!D26,2)," → ",ROUND(H4a_MODERATION!D27,2)) -> -0,42 → -0,27 → 0,03 | D34: Gradient ✓ | E34: CONFIRMÉE (direction)
A35: H4b-1: SMF → SS | B35: Spearman | C35: =H4b_SCEPTICISME!E19 -> 0.18957621 | D35: =H4b_SCEPTICISME!H19 -> 0.12441186 | E35: INFIRMÉE
A36: H4b-2: SRP → SS | B36: Spearman | C36: =H4b_SCEPTICISME!E20 -> 0.11261127 | D36: =H4b_SCEPTICISME!H20 -> 0.36424451 | E36: INFIRMÉE
B38: 🔬 TESTS DÉSAGRÉGÉS SIGNIFICATIFS
A39: Test | B39: ρ | C39: p-value | D39: Sig. | E39: Interprétation
A40: Q7_Rédaction → Q1 | B40: =H1_SUP_Q1!E51 -> 0.32557697 | C40: =H1_SUP_Q1!H51 -> 0.0071776759 | D40: ** | E40: Utilité qualité rédaction → usage
A41: Q10 (Intégration) → Q1 | B41: =H2_SFU_Q1!C31 -> 0.49220464 | C41: =H2_SFU_Q1!F31 -> 2.3313129e-05 | D41: *** | E41: Intégration workflow = facteur clé
A42: Q15 (Responsabilité) → Q17 | B42: =H3_SRP!C37 -> 0.30449358 | C42: =H3_SRP!F37 -> 0.012235357 | D42: * | E42: Risque responsabilité = principal frein
A43: Q20 (Orienter) → Q1 | B43: =H4a_MODERATION!E34 -> 0.3785463 | C43: =H4a_MODERATION!H34 -> 0.0015849524 | D43: ** | E43: Compétence prompting → usage
A44: Q21 (Détecter) → Q1 | B44: =H4a_MODERATION!E35 -> 0.24221211 | C44: =H4a_MODERATION!H35 -> 0.048291532 | D44: * | E44: Compétence détection → usage
B46: ⚠️ BIAIS D'AUTOMATISATION DÉTECTÉ (H4b)
A47: Signal | B47: ρ | C47: p-value | D47: Sig. | E47: Mécanisme
...

Sheet DONNEES BRUTES non filtrées
A1: Horodateur | B1: Q1. À quelle fréquence utilisez-vous l'IA générative dans le cadre de votre travail en audit ? | C1: Q2. Quel type d'IAG utilisez-vous principalement ? | D1: Q3. Quelles IAG utilisez vous dans le cadre de vos missions d'audit ? [Mistral] | E1: Q3. Quelles IAG utilisez vous dans le cadre de vos missions d'audit ? [Copilot] | F1: Q3. Quelles IAG utilisez vous dans le cadre de vos missions d'audit ? [ChatGPT] | G1: Q3. Quelles IAG utilisez vous dans le cadre de vos missions d'audit ? [Gemini] | H1: Q3. Quelles IAG utilisez vous dans le cadre de vos missions d'audit ? [Perplexity] | I1: Q3. Quelles IAG utilisez vous dans le cadre de vos missions d'audit ? [Grok] | J1: Q3. Quelles IAG utilisez vous dans le cadre de vos missions d'audit ? [Claude] | K1: Q3. Quelles IAG utilisez vous dans le cadre de vos missions d'audit ? [Outils IAG spécifiques cabinet] | L1: Q3. Quelles IAG utilisez vous dans le cadre de vos missions d'audit ? [Autres] | M1: Q4. Parmi ces tâches, cochez celles que vous avez déjà effectuées à l’aide de l’IA générative. | N1: Q5. Vous utilisez l'IA générative... | O1: Q6. Dans quelle mesure jugez-vous utile l’IA générative, pour améliorer la productivité, pour les activités suivantes ? [Extraction données (financières, juridiques, ...)] | P1: Q6. Dans quelle mesure jugez-vous utile l’IA générative, pour améliorer la productivité, pour les activités suivantes ? [Résumé données (financières, juridiques, ...)] | Q1: Q6. Dans quelle mesure jugez-vous utile l’IA générative, pour améliorer la productivité, pour les activités suivantes ? [Rédaction (rapports, synthèses, notes, mails)] | R1: Q6. Dans quelle mesure jugez-vous utile l’IA générative, pour améliorer la productivité, pour les activités suivantes ? [Rapprochement/Comparaison de documents] | S1: Q6. Dans quelle mesure jugez-vous utile l’IA générative, pour améliorer la productivité, pour les activités suivantes ? [Développement (scripts SQL, VBA)] | T1: Q6. Dans quelle mesure jugez-vous utile l’IA générative, pour améliorer la productivité, pour les activités suivantes ? [Détection de fraude] | U1: Q6. Dans quelle mesure jugez-vous utile l’IA générative, pour améliorer la productivité, pour les activités suivantes ? [Calcul du seuil de signification] | V1: Q6. Dans quelle mesure jugez-vous utile l’IA générative, pour améliorer la productivité, pour les activités suivantes ? [Revue d'estimations (provisions)] | W1: Q6. Dans quelle mesure jugez-vous utile l’IA générative, pour améliorer la productivité, pour les activités suivantes ? [Aide à la décision] | X1: Q6. Dans quelle mesure jugez-vous utile l’IA générative, pour améliorer la productivité, pour les activités suivantes ? [Préparation de données (format, structuration, harmonisation des valeurs)] | Y1: Q7. Dans quelle mesure jugez-vous utile l’IA générative, pour améliorer la qualité, pour les activités suivantes ? [Extraction données (financières, juridiques, ...)] | Z1: Q7. Dans quelle mesure jugez-vous utile l’IA générative, pour améliorer la qualité, pour les activités suivantes ? [Résumé données (financières, juridiques, ...)] | AA1: Q7. Dans quelle mesure jugez-vous utile l’IA générative, pour améliorer la qualité, pour les activités suivantes ? [Rédaction (rapports, synthèses, notes, mails)] | AB1: Q7. Dans quelle mesure jugez-vous utile l’IA générative, pour améliorer la qualité, pour les activités suivantes ? [Rapprochement/Comparaison de documents] | AC1: Q7. Dans quelle mesure jugez-vous utile l’IA générative, pour améliorer la qualité, pour les activités suivantes ? [Développement (scripts SQL, VBA)] | AD1: Q7. Dans quelle mesure jugez-vous utile l’IA générative, pour améliorer la qualité, pour les activités suivantes ? [Détection de fraude] | AE1: Q7. Dans quelle mesure jugez-vous utile l’IA générative, pour améliorer la qualité, pour les activités suivantes ? [Calcul du seuil de signification] | AF1: Q7. Dans quelle mesure jugez-vous utile l’IA générative, pour améliorer la qualité, pour les activités suivantes ? [Revue d'estimations (provisions)] | AG1: Q7. Dans quelle mesure jugez-vous utile l’IA générative, pour améliorer la qualité, pour les activités suivantes ? [Aide à la décision] | AH1: Q7. Dans quelle mesure jugez-vous utile l’IA générative, pour améliorer la qualité, pour les activités suivantes ? [Préparation de données (format, structuration, harmonisation des valeurs)] | AI1: Q8. "L'utilisation de l'IA générative me fait gagner du temps" | AJ1: Q9. Comment jugez-vous la prise en main des outils d'IA générative ? | AK1: Q10. "L'intégration de l'IA générative dans mon flux de travail quotidien se fait naturellement." | AL1: Q11. "Apprendre à utiliser l'IA générative efficacement requiert une formation" | AM1: Q12. L'IA générative peut produire des informations inexactes ou trompeuses dans le contexte de l'audit. | AN1: Q13. Partager des données avec l'IA générative présente des risques pour la confidentialité. | AO1: Q14. La nature opaque des modèles d'IA générative (« boîte noire ») rend difficile de comprendre et de justifier comment les résultats ont été produits en audit. | AP1: Q15. Je m'inquiète d'être tenu pour responsable si l'IAG fait une erreur dans mon travail. | AQ1: Q16 . Quel est le niveau d'importance de ce risque pour votre travail? [Hallucinations : Production d'informations fausses mais crédibles.] | AR1: Q16 . Quel est le niveau d'importance de ce risque pour votre travail? [Confidentialité : Risque de fuite ou d'usage illicite de données clients.] | AS1: Q16 . Quel est le niveau d'importance de ce risque pour votre travail? [Boîte noire : Opacité des algorithmes et difficulté à justifier un résultat.] | AT1: Q16 . Quel est le niveau d'importance de ce risque pour votre travail? [Responsabilité : Risque d'assumer seul les erreurs commises par l'IA.] | AU1: Q17. Ces risques m'empêchent d'augmenter mon usage de l'IAG | AV1: Q18. Si les risques étaient éliminés, j'utiliserais davantage l'IAG | AW1: Q19. Votre niveau global de formation (interne ou auto-apprentissage) ? | AX1: Q20. "Je me sens capable d'orienter les réponses de l'IAG pour limiter les risques d'imprécisions ou d'erreurs." | AY1: Q21. "Je me sens capable d'identifier les erreurs générées par l'IAG." | AZ1: Q22. Lorsque l’IAG vous propose un résultat, il vous arrive de vous y fier sans vérifier en détail par vous‑même. | BA1: Q23. À quelle fréquence vérifiez vous la source d'origine face à une réponse de l'IAG ? | BB1: Q24. Estimez-vous que votre jugement professionnel en audit reste fort malgré l'utilisation régulière de l'IAG? | BC1: Q25. "Il m'arrive de remettre en question mon jugement professionnel quand l'IAG me propose une conclusion différente de la mienne" | BD1: Q26. "En pratique, il m'arrive de conclure avant d'avoir réuni toutes les preuves que je jugerais idéalement nécessaires" | BE1: Q27. Prévoyez vous d'augmenter votre usage de l'IAG dans les 6 prochains mois ? | BF1: Q28. Probabilité d'augmenter votre usage de l'IAG si vous receviez une formation à l'avenir ? | BG1: Q29. Pour garantir la précision statistique des résultats, merci de sélectionner la réponse 'Neutre' ici. | BH1: Q30. Quelle est votre perception sur l'équilibre bénéfices-risques de l'IAG en audit ? | BI1: Q31. Tranche d'âge | BJ1: Q32. Genre | BK1: Q33. Votre niveau hiérarchique | BL1: Q34. Votre nombre d'années d'expérience | BM1: Q35. Votre cœur de métier | BN1: Q36. Taille de votre cabinet | BO1: Avant de terminer, souhaitez-vous partager votre opinion ou vos impressions sur l’IA générative ? (facultatif)
A2: 46035.409 | B2: 3. Rarement (1 à 3 fois par mois) | C2: Outils grand public (ex: ChatGPT, Gemini ) | E2: Version grand public | F2: Version grand public | G2: Version grand public | J2: Version entreprise | M2: Reformulation ou traduction de documents | N2: De manière VOLONTAIRE (vous avez choisi vous-même) | O2: 1. Pas du tout utile | P2: 2. Peu utile | Q2: 2. Peu utile | R2: 1. Pas du tout utile | S2: 2. Peu utile | T2: 1. Pas du tout utile | U2: 1. Pas du tout utile | V2: 1. Pas du tout utile | W2: 2. Peu utile | X2: 2. Peu utile | Y2: 1. Pas du tout utile | Z2: 1. Pas du tout utile | AA2: 2. Peu utile | AB2: 1. Pas du tout utile | AC2: 1. Pas du tout utile | AD2: 1. Pas du tout utile | AE2: 1. Pas du tout utile | AF2: 2. Peu utile | AG2: 2. Peu utile | AH2: 1. Pas du tout utile | AI2: 2 | AJ2: 5. Plutôt facile (Assez intuitif) | AK2: 5. Plutôt d'accord (S'intègre assez bien) | AL2: 2 | AM2: 7 | AN2: 7 | AO2: 4 | AP2: 7 | AQ2: 5. Très important | AR2: 5. Très important | AS2: 4. Important | AT2: 5. Très important | AU2: 4 | AV2: 5 | AW2: 4. Moyenne (Environ une journée de formation cumulée) | AX2: 7 | AY2: 7 | AZ2: 2. En désaccord (Je contrôle la quasi-totalité des éléments) | BA2: 6 | BB2: 7 | BC2: 1 | BD2: 1 | BE2: Je compte réduire l’utilisation de l’IA | BF2: 1 | BG2: 4. Neutre | BH2: 1 | BI2: 26-35 | BJ2: Femme | BK2: Senior | BL2: 2 - 3 ans | BM2: Audit Financier | BN2: Cabinet international | BO2: L’IA est une bonne tentative mais le cerveau humain reste meilleur, dans un métier d’audit financier qui est très sensible on peut utiliser l’IA pour nous informer sur des lois, de la comptabilité, des méthodes de calculs etc mais jamais pour émettre un rapport d’audit, le comissaire aux compte est un professionnel dans son domaine qui a fait plusieurs années d’études et d’expérience impossible qu’un rebot soit plus performant que lui.
A3: 46036.706 | B3: 5. Régulièrement (Plusieurs fois par semaine) | C3: Outils fournis/agréés par le cabinet (ex: Copilot sécurisé) | E3: Version grand public | M3: Recherche d'informations ou de points techniques, Rédaction (rapports, synthèses, notes, mails), Reformulation ou traduction de documents | N3: De manière VOLONTAIRE (vous avez choisi vous-même) | O3: 1. Pas du tout utile | P3: 2. Peu utile | Q3: 5. Très utile | R3: 2. Peu utile | S3: 2. Peu utile | T3: 1. Pas du tout utile | U3: 1. Pas du tout utile | V3: 1. Pas du tout utile | W3: 1. Pas du tout utile | X3: 3. Neutre | Y3: 1. Pas du tout utile | Z3: 2. Peu utile | AA3: 5. Très utile | AB3: 2. Peu utile | AC3: 2. Peu utile | AD3: 1. Pas du tout utile | AE3: 1. Pas du tout utile | AF3: 1. Pas du tout utile | AG3: 1. Pas du tout utile | AH3: 3. Neutre | AI3: 6 | AJ3: 5. Plutôt facile (Assez intuitif) | AK3: 6. D'accord (S'intègre facilement) | AL3: 4 | AM3: 7 | AN3: 4 | AO3: 7 | AP3: 7 | AQ3: 5. Très important | AR3: 4. Important | AS3: 4. Important | AT3: 5. Très important | AU3: 4 | AV3: 4 | AW3: 3. Faible (Moins de 5 heures de formation au total) | AX3: 5 | AY3: 5 | AZ3: 3. Plutôt en désaccord (Je procède à une revue importante) | BA3: 5 | BB3: 6 | BC3: 5 | BD3: 3 | BE3: Oui | BF3: 5 | BG3: 4. Neutre | BH3: 6 | BI3: 18-25 | BJ3: Homme | BK3: Junior | BL3: Moins de 2 ans | BM3: Audit Financier | BN3: Cabinet international
A4: 46036.707 | B4: 5. Régulièrement (Plusieurs fois par semaine) | C4: Outils fournis/agréés par le cabinet (ex: Copilot sécurisé) | E4: Version entreprise | F4: Version grand public | K4: Version entreprise | M4: Rapprochement/Comparaison de documents, Correction et mise en cohérence de documents, Rédaction (rapports, synthèses, notes, mails), Préparation de données (format, structuration, harmonisation des valeurs) | N4: De manière VOLONTAIRE (vous avez choisi vous-même) | O4: 4. Utile | P4: 4. Utile | Q4: 5. Très utile | R4: 2. Peu utile | S4: 2. Peu utile | T4: 3. Neutre | U4: 3. Neutre | V4: 3. Neutre | W4: 3. Neutre | X4: 4. Utile | Y4: 4. Utile | Z4: 4. Utile | AA4: 4. Utile | AB4: 4. Utile | AC4: 2. Peu utile | AD4: 2. Peu utile | AE4: 2. Peu utile | AF4: 2. Peu utile | AG4: 4. Utile | AH4: 4. Utile | AI4: 7 | AJ4: 5. Plutôt facile (Assez intuitif) | AK4: 1. Tout à fait en désaccord (Friction totale / Inutilisable) | AL4: 5 | AM4: 1 | AN4: 4 | AO4: 4 | AP4: 6 | AQ4: 4. Important | AR4: 4. Important | AS4: 4. Important | AT4: 4. Important | AU4: 5 | AV4: 5 | AW4: 5. Solide (Plusieurs jours de formation ou modules suivis) | AX4: 6 | AY4: 5 | AZ4: 4. Neutre (Le niveau de vérification dépend de la complexité) | BA4: 5 | BB4: 4 | BC4: 6 | BD4: 4 | BE4: Oui | BF4: 7 | BG4: 4. Neutre | BH4: 3 | BI4: 18-25 | BJ4: Femme | BK4: Junior | BL4: Moins de 2 ans | BM4: Audit Financier | BN4: Cabinet international
A5: 46036.712 | B5: 7. Très fréquemment (Plusieurs fois par jour) | C5: Usage mix des deux | E5: Version entreprise | F5: Version grand public | G5: Version grand public | K5: Version entreprise | M5: Automatisation et création de scripts (SQL, VBA), Recherche d'informations ou de points techniques, Analyse de données et génération d'insights, Rédaction (rapports, synthèses, notes, mails), Évaluation du contrôle interne, Préparation de données (format, structuration, harmonisation des valeurs) | N5: De manière VOLONTAIRE (vous avez choisi vous-même) | O5: 5. Très utile | P5: 5. Très utile | Q5: 5. Très utile | R5: 3. Neutre | S5: 5. Très utile | T5: 3. Neutre | U5: 3. Neutre | V5: 3. Neutre | W5: 4. Utile | X5: 5. Très utile | Y5: 5. Très utile | Z5: 4. Utile | AA5: 5. Très utile | AB5: 4. Utile | AC5: 5. Très utile | AD5: 3. Neutre | AE5: 3. Neutre | AF5: 3. Neutre | AG5: 3. Neutre | AH5: 5. Très utile | AI5: 7 | AJ5: 6. Facile (Maîtrise rapide) | AK5: 6. D'accord (S'intègre facilement) | AL5: 4 | AM5: 4 | AN5: 7 | AO5: 5 | AP5: 6 | AQ5: 3. Moyennement important | AR5: 5. Très important | AS5: 4. Important | AT5: 4. Important | AU5: 4 | AV5: 6 | AW5: 3. Faible (Moins de 5 heures de formation au total) | AX5: 5 | AY5: 4 | AZ5: 4. Neutre (Le niveau de vérification dépend de la complexité) | BA5: 4 | BB5: 6 | BC5: 6 | BD5: 4 | BE5: Oui | BF5: 6 | BG5: 4. Neutre | BH5: 5 | BI5: 18-25 | BJ5: Homme | BK5: Junior | BL5: Moins de 2 ans | BM5: Audit IT | BN5: Cabinet international
A6: 46036.713 | B6: 5. Régulièrement (Plusieurs fois par semaine) | C6: Outils fournis/agréés par le cabinet (ex: Copilot sécurisé) | E6: Version entreprise | M6: Reformulation ou traduction de documents, Préparation de données (format, structuration, harmonisation des valeurs), Recherche d'informations ou de points techniques | N6: De manière VOLONTAIRE (vous avez choisi vous-même) | O6: 5. Très utile | P6: 5. Très utile | Q6: 4. Utile | R6: 5. Très utile | S6: 5. Très utile | T6: 4. Utile | U6: 1. Pas du tout utile | V6: 4. Utile | W6: 4. Utile | X6: 5. Très utile | Y6: 5. Très utile | Z6: 5. Très utile | AA6: 5. Très utile | AB6: 5. Très utile | AC6: 5. Très utile | AD6: 5. Très utile | AE6: 5. Très utile | AF6: 5. Très utile | AG6: 5. Très utile | AH6: 5. Très utile | AI6: 6 | AJ6: 6. Facile (Maîtrise rapide) | AK6: 6. D'accord (S'intègre facilement) | AL6: 3 | AM6: 6 | AN6: 6 | AO6: 6 | AP6: 4 | AQ6: 5. Très important | AR6: 5. Très important | AS6: 5. Très important | AT6: 5. Très important | AU6: 6 | AV6: 7 | AW6: 1. Aucune | AX6: 5 | AY6: 6 | AZ6: 5. Plutôt d'accord (Je vérifie uniquement les points clés) | BA6: 4 | BB6: 6 | BC6: 5 | BD6: 2 | BE6: aucune idée | BF6: 4 | BG6: 4. Neutre | BH6: 5 | BI6: 18-25 | BJ6: Homme | BK6: Stagiaire | BL6: Moins de 2 ans | BM6: Audit Financier | BN6: Cabinet international
A7: 46036.716 | B7: 5. Régulièrement (Plusieurs fois par semaine) | C7: Outils fournis/agréés par le cabinet (ex: Copilot sécurisé) | E7: Version entreprise | M7: Reformulation ou traduction de documents, Rédaction (rapports, synthèses, notes, mails), Préparation de données (format, structuration, harmonisation des valeurs), Correction et mise en cohérence de documents | N7: De manière VOLONTAIRE (vous avez choisi vous-même) | O7: 3. Neutre | P7: 5. Très utile | Q7: 5. Très utile | R7: 3. Neutre | S7: 1. Pas du tout utile | T7: 1. Pas du tout utile | U7: 1. Pas du tout utile | V7: 1. Pas du tout utile | W7: 1. Pas du tout utile | X7: 4. Utile | Y7: 4. Utile | Z7: 5. Très utile | AA7: 5. Très utile | AB7: 3. Neutre | AC7: 1. Pas du tout utile | AD7: 1. Pas du tout utile | AE7: 1. Pas du tout utile | AF7: 1. Pas du tout utile | AG7: 1. Pas du tout utile | AH7: 1. Pas du tout utile | AI7: 5 | AJ7: 5. Plutôt facile (Assez intuitif) | AK7: 5. Plutôt d'accord (S'intègre assez bien) | AL7: 5 | AM7: 5 | AN7: 5 | AO7: 4 | AP7: 2 | AQ7: 5. Très important | AR7: 5. Très important | AS7: 5. Très important | AT7: 5. Très important | AU7: 4 | AV7: 5 | AW7: 4. Moyenne (Environ une journée de formation cumulée) | AX7: 6 | AY7: 6 | AZ7: 2. En désaccord (Je contrôle la quasi-totalité des éléments) | BA7: 6 | BB7: 6 | BC7: 5 | BD7: 2 | BE7: Non | BF7: 4 | BG7: 4. Neutre | BH7: 4 | BI7: 18-25 | BJ7: Femme | BK7: Junior | BL7: Moins de 2 ans | BM7: Audit Financier | BN7: Cabinet international
A8: 46036.721 | B8: 3. Rarement (1 à 3 fois par mois) | C8: Outils fournis/agréés par le cabinet (ex: Copilot sécurisé) | E8: Version entreprise | M8: Formules Excel, aide pour l'utilisation des outils Microsoft | N8: De manière RECOMMANDÉE (cabinet encourage, mais facultatif) | O8: 3. Neutre | P8: 5. Très utile | Q8: 4. Utile | R8: 4. Utile | S8: 3. Neutre | T8: 1. Pas du tout utile | U8: 1. Pas du tout utile | V8: 1. Pas du tout utile | W8: 3. Neutre | X8: 4. Utile | Y8: 3. Neutre | Z8: 4. Utile | AA8: 4. Utile | AB8: 4. Utile | AC8: 3. Neutre | AD8: 1. Pas du tout utile | AE8: 1. Pas du tout utile | AF8: 1. Pas du tout utile | AG8: 3. Neutre | AH8: 4. Utile | AI8: 5 | AJ8: 6. Facile (Maîtrise rapide) | AK8: 3. Plutôt en désaccord (Demande un effort conscient) | AL8: 6 | AM8: 7 | AN8: 6 | AO8: 6 | AP8: 2 | AQ8: 5. Très important | AR8: 5. Très important | AS8: 4. Important | AT8: 3. Moyennement important | AU8: 6 | AV8: 7 | AW8: 4. Moyenne (Environ une journée de formation cumulée) | AX8: 4 | AY8: 4 | AZ8: 2. En désaccord (Je contrôle la quasi-totalité des éléments) | BA8: 7 | BB8: 5 | BC8: 5 | BD8: 2 | BE8: Oui | BF8: 6 | BG8: 4. Neutre | BH8: 4 | BI8: 26-35 | BJ8: Femme | BK8: Junior | BL8: Moins de 2 ans | BM8: Audit Financier | BN8: Cabinet international
A9: 46036.725 | B9: 3. Rarement (1 à 3 fois par mois) | C9: Outils fournis/agréés par le cabinet (ex: Copilot sécurisé) | E9: Version entreprise | M9: Reformulation ou traduction de documents, Recherche d'informations ou de points techniques | N9: De manière RECOMMANDÉE (cabinet encourage, mais facultatif) | O9: 4. Utile | P9: 4. Utile | Q9: 2. Peu utile | R9: 2. Peu utile | S9: 3. Neutre | T9: 1. Pas du tout utile | U9: 1. Pas du tout utile | V9: 1. Pas du tout utile | W9: 2. Peu utile | X9: 4. Utile | Y9: 4. Utile | Z9: 3. Neutre | AA9: 2. Peu utile | AB9: 2. Peu utile | AC9: 2. Peu utile | AD9: 2. Peu utile | AE9: 1. Pas du tout utile | AF9: 2. Peu utile | AG9: 2. Peu utile | AH9: 4. Utile | AI9: 4 | AJ9: 6. Facile (Maîtrise rapide) | AK9: 5. Plutôt d'accord (S'intègre assez bien) | AL9: 3 | AM9: 7 | AN9: 3 | AO9: 7 | AP9: 7 | AQ9: 5. Très important | AR9: 5. Très important | AS9: 4. Important | AT9: 3. Moyennement important | AU9: 6 | AV9: 5 | AW9: 3. Faible (Moins de 5 heures de formation au total) | AX9: 5 | AY9: 5 | AZ9: 4. Neutre (Le niveau de vérification dépend de la complexité) | BA9: 5 | BB9: 4 | BC9: 5 | BD9: 2 | BE9: Non | BF9: 3 | BG9: 4. Neutre | BH9: 5 | BI9: 18-25 | BJ9: Homme | BK9: Alternant | BL9: Moins de 2 ans | BM9: Audit Financier | BN9: Cabinet international
A10: 46036.867 | B10: 4. Parfois (Environ une fois par semaine) | C10: Usage mix des deux | E10: Version entreprise | F10: Version grand public | M10: Revue d'estimations comptables (provisions, dépréciations), Reformulation ou traduction de documents, Rapprochement/Comparaison de documents, Aide à la décision, Rédaction (rapports, synthèses, notes, mails) | N10: De manière VOLONTAIRE (vous avez choisi vous-même) | O10: 2. Peu utile | P10: 4. Utile | Q10: 5. Très utile | R10: 3. Neutre | S10: 4. Utile | T10: 3. Neutre | U10: 3. Neutre | V10: 4. Utile | W10: 4. Utile | X10: 3. Neutre | Y10: 1. Pas du tout utile | Z10: 1. Pas du tout utile | AA10: 1. Pas du tout utile | AB10: 1. Pas du tout utile | AC10: 1. Pas du tout utile | AD10: 1. Pas du tout utile | AE10: 1. Pas du tout utile | AF10: 1. Pas du tout utile | AG10: 1. Pas du tout utile | AH10: 1. Pas du tout utile | AI10: 7 | AJ10: 7. Très facile (Instinctif / Sans aide) | AK10: 6. D'accord (S'intègre facilement) | AL10: 3 | AM10: 5 | AN10: 7 | AO10: 7 | AP10: 7 | AQ10: 4. Important | AR10: 4. Important | AS10: 4. Important | AT10: 4. Important | AU10: 5 | AV10: 7 | AW10: 6. Approfondie (Parcours certifiant ou auto-formation technique longue) | AX10: 4 | AY10: 4 | AZ10: 1. Pas du tout d’accord (Je vérifie systématiquement chaque détail) | BA10: 6 | BB10: 5 | BC10: 5 | BD10: 6 | BE10: Oui | BF10: 7 | BG10: 4. Neutre | BH10: NA | BI10: 18-25 | BJ10: Femme | BK10: Junior | BL10: Moins de 2 ans | BM10: Audit Financier | BN10: Cabinet international
A11: 46036.891 | B11: 4. Parfois (Environ une fois par semaine) | C11: Outils fournis/agréés par le cabinet (ex: Copilot sécurisé) | E11: Version entreprise | M11: Reformulation ou traduction de documents, Recherche d'informations ou de points techniques, Rédaction (rapports, synthèses, notes, mails) | N11: De manière VOLONTAIRE (vous avez choisi vous-même) | O11: 5. Très utile | P11: 4. Utile | Q11: 5. Très utile | R11: 3. Neutre | S11: 4. Utile | T11: 2. Peu utile | U11: 2. Peu utile | V11: 3. Neutre | W11: 3. Neutre | X11: 3. Neutre | Y11: 4. Utile | Z11: 5. Très utile | AA11: 5. Très utile | AB11: 3. Neutre | AC11: 4. Utile | AD11: 2. Peu utile | AE11: 2. Peu utile | AF11: 3. Neutre | AG11: 4. Utile | AH11: 3. Neutre | AI11: 7 | AJ11: 7. Très facile (Instinctif / Sans aide) | AK11: 5. Plutôt d'accord (S'intègre assez bien) | AL11: 3 | AM11: 7 | AN11: 7 | AO11: 1 | AP11: 7 | AQ11: 3. Moyennement important | AR11: 5. Très important | AS11: 1. Pas du tout important | AT11: 4. Important | AU11: 6 | AV11: 7 | AW11: 3. Faible (Moins de 5 heures de formation au total) | AX11: 5 | AY11: 6 | AZ11: 4. Neutre (Le niveau de vérification dépend de la complexité) | BA11: 5 | BB11: 6 | BC11: 2 | BD11: 2 | BE11: Oui | BF11: 7 | BG11: 4. Neutre | BH11: 5 | BI11: 18-25 | BJ11: Homme | BK11: Junior | BL11: Moins de 2 ans | BM11: Audit Financier | BN11: Cabinet local
A12: 46037.405 | B12: 7. Très fréquemment (Plusieurs fois par jour) | C12: Outils grand public (ex: ChatGPT, Gemini ) | F12: Version grand public | M12: Rédaction (rapports, synthèses, notes, mails), Préparation de données (format, structuration, harmonisation des valeurs), Correction et mise en cohérence de documents, Reformulation ou traduction de documents | N12: De manière VOLONTAIRE (vous avez choisi vous-même) | O12: 4. Utile | P12: 4. Utile | Q12: 5. Très utile | R12: 5. Très utile | S12: 3. Neutre | T12: 3. Neutre | U12: 3. Neutre | V12: 3. Neutre | W12: 4. Utile | X12: 5. Très utile | Y12: 4. Utile | Z12: 4. Utile | AA12: 5. Très utile | AB12: 5. Très utile | AC12: 3. Neutre | AD12: 3. Neutre | AE12: 3. Neutre | AF12: 3. Neutre | AG12: 4. Utile | AH12: 5. Très utile | AI12: 7 | AJ12: 7. Très facile (Instinctif / Sans aide) | AK12: 7. Tout à fait d'accord (Automatisme quotidien) | AL12: 4 | AM12: 6 | AN12: 4 | AO12: 4 | AP12: 1 | AQ12: 4. Important | AR12: 3. Moyennement important | AS12: 3. Moyennement important | AT12: 3. Moyennement important | AU12: 1 | AV12: 2 | AW12: 3. Faible (Moins de 5 heures de formation au total) | AX12: 7 | AY12: 6 | AZ12: 3. Plutôt en désaccord (Je procède à une revue importante) | BA12: 1 | BB12: 4 | BC12: 4 | BD12: 4 | BE12: Oui | BF12: 7 | BG12: 4. Neutre | BH12: 4 | BI12: +65 | BJ12: Homme | BK12: Manager | BL12: Plus de 10 ans | BM12: RECRUTEMENT | BN12: Cabinet local
A13: 46037.416 | B13: 7. Très fréquemment (Plusieurs fois par jour) | C13: Usage mix des deux | E13: Version entreprise | F13: Version grand public | G13: Version grand public | J13: Version entreprise | K13: Version entreprise | M13: Évaluation du contrôle interne, Automatisation et création de scripts (SQL, VBA), Reformulation ou traduction de documents, Rédaction (rapports, synthèses, notes, mails) | N13: De manière VOLONTAIRE (vous avez choisi vous-même) | O13: 1. Pas du tout utile | P13: 3. Neutre | Q13: 5. Très utile | R13: 5. Très utile | S13: 5. Très utile | T13: 3. Neutre | U13: 2. Peu utile | V13: 2. Peu utile | W13: 1. Pas du tout utile | X13: 3. Neutre | Y13: 4. Utile | Z13: 4. Utile | AA13: 4. Utile | AB13: 4. Utile | AC13: 5. Très utile | AD13: 2. Peu utile | AE13: 2. Peu utile | AF13: 4. Utile | AG13: 3. Neutre | AH13: 4. Utile | AI13: 5 | AJ13: 7. Très facile (Instinctif / Sans aide) | AK13: 6. D'accord (S'intègre facilement) | AL13: 5 | AM13: 7 | AN13: 7 | AO13: 7 | AP13: 7 | AQ13: 5. Très important | AR13: 5. Très important | AS13: 5. Très important | AT13: 5. Très important | AU13: 4 | AV13: 6 | AW13: 3. Faible (Moins de 5 heures de formation au total) | AX13: 6 | AY13: 6 | AZ13: 4. Neutre (Le niveau de vérification dépend de la complexité) | BA13: 7 | BB13: 7 | BC13: 7 | BD13: 2 | BE13: Oui | BF13: 7 | BG13: 4. Neutre | BH13: 7 | BI13: 18-25 | BJ13: Homme | BK13: Junior | BL13: 2 - 3 ans | BM13: Audit Financier | BN13: Cabinet local
A14: 46037.658 | B14: 7. Très fréquemment (Plusieurs fois par jour) | C14: Usage mix des deux | D14: Version grand public | E14: Version entreprise | F14: Version grand public, Version entreprise | G14: Version entreprise | I14: Version grand public | J14: Version entreprise | M14: Recherche d'informations ou de points techniques, Correction et mise en cohérence de documents, Analyse de données et génération d'insights, Rédaction (rapports, synthèses, notes, mails), Reformulation ou traduction de documents | N14: De manière RECOMMANDÉE (cabinet encourage, mais facultatif) | O14: 1. Pas du tout utile | P14: 4. Utile | Q14: 5. Très utile | R14: 5. Très utile | S14: 5. Très utile | T14: 3. Neutre | U14: 3. Neutre | V14: 3. Neutre | W14: 4. Utile | X14: 3. Neutre | Y14: 3. Neutre | Z14: 4. Utile | AA14: 5. Très utile | AB14: 4. Utile | AC14: 4. Utile | AD14: 3. Neutre | AE14: 3. Neutre | AF14: 3. Neutre | AG14: 3. Neutre | AH14: 3. Neutre | AI14: 7 | AJ14: 7. Très facile (Instinctif / Sans aide) | AK14: 7. Tout à fait d'accord (Automatisme quotidien) | AL14: 2 | AM14: 7 | AN14: 7 | AO14: 5 | AP14: 6 | AQ14: 5. Très important | AR14: 5. Très important | AS14: 4. Important | AT14: 4. Important | AU14: 1 | AV14: 4 | AW14: 6. Approfondie (Parcours certifiant ou auto-formation technique longue) | AX14: 7 | AY14: 7 | AZ14: 1. Pas du tout d’accord (Je vérifie systématiquement chaque détail) | BA14: 6 | BB14: 6 | BC14: 7 | BD14: 1 | BE14: Oui | BF14: 7 | BG14: 4. Neutre | BH14: 7 | BI14: 26-35 | BJ14: Homme | BK14: Senior Manager | BL14: Plus de 10 ans | BM14: Audit IT | BN14: Cabinet international | BO14: Pour moi l'IA générative est comme un super stagiaire : il ne peut pas être responsable et on doit vérifier son travail (car il y a probablement des erreurs). Le plus grand risque selon moi est pour les personnes avec peu d'expérience "métier", qui vont s'appuyer sur l'IA sans être en capacité d'identifier les erreurs.
A15: 46038.388 | B15: 6. Quotidiennement (Une fois par jour) | C15: Outils fournis/agréés par le cabinet (ex: Copilot sécurisé) | E15: Version entreprise | M15: Reformulation ou traduction de documents, Rédaction (rapports, synthèses, notes, mails), Automatisation et création de scripts (SQL, VBA) | N15: De manière RECOMMANDÉE (cabinet encourage, mais facultatif) | O15: 5. Très utile | P15: 5. Très utile | Q15: 5. Très utile | R15: 3. Neutre | S15: 5. Très utile | T15: 2. Peu utile | U15: 2. Peu utile | V15: 2. Peu utile | W15: 3. Neutre | X15: 4. Utile | Y15: 3. Neutre | Z15: 5. Très utile | AA15: 5. Très utile | AB15: 4. Utile | AC15: 5. Très utile | AD15: 3. Neutre | AE15: 1. Pas du tout utile | AF15: 2. Peu utile | AG15: 3. Neutre | AH15: 4. Utile | AI15: 6 | AJ15: 7. Très facile (Instinctif / Sans aide) | AK15: 6. D'accord (S'intègre facilement) | AL15: 2 | AM15: 7 | AN15: 4 | AO15: 7 | AP15: 6 | AQ15: 4. Important | AR15: 5. Très important | AS15: 3. Moyennement important | AT15: 5. Très important | AU15: 4 | AV15: 7 | AW15: 6. Approfondie (Parcours certifiant ou auto-formation technique longue) | AX15: 5 | AY15: 3 | AZ15: 4. Neutre (Le niveau de vérification dépend de la complexité) | BA15: 5 | BB15: 4 | BC15: 6 | BD15: 3 | BE15: Non | BF15: 2 | BG15: 4. Neutre | BH15: 6 | BI15: 18-25 | BJ15: Homme | BK15: Junior | BL15: 6 - 7 ans | BM15: Audit Financier | BN15: Cabinet régional
A16: 46038.531 | B16: 5. Régulièrement (Plusieurs fois par semaine) | C16: Usage mix des deux | E16: Version grand public | M16: Recherche d'informations ou de points techniques, Aide à la décision, Rédaction (rapports, synthèses, notes, mails), Reformulation ou traduction de documents, Correction et mise en cohérence de documents | N16: De manière RECOMMANDÉE (cabinet encourage, mais facultatif) | O16: 1. Pas du tout utile | P16: 5. Très utile | Q16: 5. Très utile | R16: 1. Pas du tout utile | S16: 1. Pas du tout utile | T16: 1. Pas du tout utile | U16: 1. Pas du tout utile | V16: 1. Pas du tout utile | W16: 5. Très utile | X16: 3. Neutre | Y16: 1. Pas du tout utile | Z16: 1. Pas du tout utile | AA16: 5. Très utile | AB16: 4. Utile | AC16: 1. Pas du tout utile | AD16: 1. Pas du tout utile | AE16: 1. Pas du tout utile | AF16: 1. Pas du tout utile | AG16: 5. Très utile | AH16: 3. Neutre | AI16: 5 | AJ16: 6. Facile (Maîtrise rapide) | AK16: 6. D'accord (S'intègre facilement) | AL16: 3 | AM16: 6 | AN16: 4 | AO16: 6 | AP16: 5 | AQ16: 5. Très important | AR16: 3. Moyennement important | AS16: 3. Moyennement important | AT16: 3. Moyennement important | AU16: 2 | AV16: 7 | AW16: 5. Solide (Plusieurs jours de formation ou modules suivis) | AX16: 5 | AY16: 5 | AZ16: 5. Plutôt d'accord (Je vérifie uniquement les points clés) | BA16: 5 | BB16: 5 | BC16: 4 | BD16: 6 | BE16: Oui | BF16: 6 | BG16: 6. D’accord | BH16: 5 | BI16: 18-25 | BJ16: Homme | BK16: Junior | BL16: Moins de 2 ans | BM16: Audit Financier | BN16: Cabinet local
A17: 46038.983 | B17: 3. Rarement (1 à 3 fois par mois) | C17: Usage mix des deux | F17: Version grand public | G17: Version grand public | H17: Version grand public | K17: Version entreprise | M17: Rédaction (rapports, synthèses, notes, mails), Recherche d'informations ou de points techniques, Revue d'estimations comptables (provisions, dépréciations), Évaluation du contrôle interne, Aide à la décision | N17: De manière VOLONTAIRE (vous avez choisi vous-même) | O17: 3. Neutre | P17: 5. Très utile | Q17: 5. Très utile | R17: 4. Utile | S17: 3. Neutre | T17: 2. Peu utile | U17: 2. Peu utile | V17: 4. Utile | W17: 4. Utile | X17: 3. Neutre | Y17: 2. Peu utile | Z17: 4. Utile | AA17: 5. Très utile | AB17: 5. Très utile | AC17: 4. Utile | AD17: 3. Neutre | AE17: 3. Neutre | AF17: 3. Neutre | AG17: 4. Utile | AH17: 3. Neutre | AI17: 4 | AJ17: 4. Ni facile, ni difficile (Prise en main normale) | AK17: 5. Plutôt d'accord (S'intègre assez bien) | AL17: 6 | AM17: 6 | AN17: 7 | AO17: 6 | AP17: 3 | AQ17: 5. Très important | AR17: 5. Très important | AS17: 3. Moyennement important | AT17: 3. Moyennement important | AU17: 4 | AV17: 5 | AW17: 5. Solide (Plusieurs jours de formation ou modules suivis) | AX17: 6 | AY17: 6 | AZ17: 4. Neutre (Le niveau de vérification dépend de la complexité) | BA17: 6 | BB17: 4 | BC17: 3 | BD17: 5 | BE17: Non | BF17: 7 | BG17: 4. Neutre | BH17: 3 | BI17: 18-25 | BJ17: Femme | BK17: Junior | BL17: 2 - 3 ans | BM17: Audit Financier | BN17: Cabinet international
A18: 46039.411 | B18: 7. Très fréquemment (Plusieurs fois par jour) | C18: Outils fournis/agréés par le cabinet (ex: Copilot sécurisé) | E18: Version entreprise | K18: Version entreprise | M18: Reformulation ou traduction de documents, Rédaction (rapports, synthèses, notes, mails), Automatisation et création de scripts (SQL, VBA) | N18: De manière VOLONTAIRE (vous avez choisi vous-même) | O18: 4. Utile | P18: 5. Très utile | Q18: 4. Utile | R18: 2. Peu utile | S18: 5. Très utile | T18: 3. Neutre | U18: 3. Neutre | V18: 2. Peu utile | W18: 3. Neutre | X18: 4. Utile | Y18: 4. Utile | Z18: 3. Neutre | AA18: 3. Neutre | AB18: 2. Peu utile | AC18: 5. Très utile | AD18: 3. Neutre | AE18: 2. Peu utile | AF18: 2. Peu utile | AG18: 2. Peu utile | AH18: 4. Utile | AI18: 5 | AJ18: 6. Facile (Maîtrise rapide) | AK18: 6. D'accord (S'intègre facilement) | AL18: 3 | AM18: 7 | AN18: 7 | AO18: 3 | AP18: 7 | AQ18: 4. Important | AR18: 5. Très important | AS18: 3. Moyennement important | AT18: 4. Important | AU18: 5 | AV18: 7 | AW18: 4. Moyenne (Environ une journée de formation cumulée) | AX18: 6 | AY18: 6 | AZ18: 3. Plutôt en désaccord (Je procède à une revue importante) | BA18: 4 | BB18: 5 | BC18: 4 | BD18: 5 | BE18: Oui | BF18: 5 | BG18: 4. Neutre | BH18: 6 | BI18: 26-35 | BJ18: Homme | BK18: Senior | BL18: 4 - 5 ans | BM18: Audit IT | BN18: Cabinet international
A19: 46040.715 | B19: 5. Régulièrement (Plusieurs fois par semaine) | C19: Outils grand public (ex: ChatGPT, Gemini ) | D19: Version grand public | E19: Version grand public | F19: Version entreprise | G19: Version grand public | H19: Version grand public | I19: Version grand public | J19: Version grand public | K19: Version entreprise | L19: Version grand public | M19: Rapprochement/Comparaison de documents, Reformulation ou traduction de documents, Correction et mise en cohérence de documents, Évaluation du contrôle interne, Préparation de données (format, structuration, harmonisation des valeurs), Recherche d'informations ou de points techniques, Rédaction (rapports, synthèses, notes, mails) | N19: De manière VOLONTAIRE (vous avez choisi vous-même) | O19: 4. Utile | P19: 5. Très utile | Q19: 4. Utile | R19: 5. Très utile | S19: 3. Neutre | T19: 4. Utile | U19: 1. Pas du tout utile | V19: 3. Neutre | W19: 5. Très utile | X19: 5. Très utile | Y19: 5. Très utile | Z19: 5. Très utile | AA19: 4. Utile | AB19: 5. Très utile | AC19: 3. Neutre | AD19: 3. Neutre | AE19: 1. Pas du tout utile | AF19: 2. Peu utile | AG19: 4. Utile | AH19: 4. Utile | AI19: 6 | AJ19: 5. Plutôt facile (Assez intuitif) | AK19: 5. Plutôt d'accord (S'intègre assez bien) | AL19: 6 | AM19: 5 | AN19: 4 | AO19: 3 | AP19: 2 | AQ19: 5. Très important | AR19: 5. Très important | AS19: 4. Important | AT19: 4. Important | AU19: 2 | AV19: 4 | AW19: 4. Moyenne (Environ une journée de formation cumulée) | AX19: 5 | AY19: 5 | AZ19: 2. En désaccord (Je contrôle la quasi-totalité des éléments) | BA19: 6 | BB19: 6 | BC19: 7 | BD19: 6 | BE19: Oui | BF19: 6 | BG19: 4. Neutre | BH19: 6 | BI19: 26-35 | BJ19: Homme | BK19: Senior | BL19: 2 - 3 ans | BM19: Audit Financier | BN19: Cabinet international
A20: 46040.793 | B20: 5. Régulièrement (Plusieurs fois par semaine) | C20: Outils fournis/agréés par le cabinet (ex: Copilot sécurisé) | K20: Version entreprise | M20: Analyse de données et génération d'insights, Rapprochement/Comparaison de documents, Recherche d'informations ou de points techniques, Préparation de données (format, structuration, harmonisation des valeurs), Reformulation ou traduction de documents, Aide à la décision | N20: De manière VOLONTAIRE (vous avez choisi vous-même) | O20: 4. Utile | P20: 4. Utile | Q20: 3. Neutre | R20: 4. Utile | S20: 4. Utile | T20: 3. Neutre | U20: 3. Neutre | V20: 3. Neutre | W20: 4. Utile | X20: 4. Utile | Y20: 4. Utile | Z20: 4. Utile | AA20: 4. Utile | AB20: 4. Utile | AC20: 4. Utile | AD20: 3. Neutre | AE20: 3. Neutre | AF20: 3. Neutre | AG20: 4. Utile | AH20: 4. Utile | AI20: 2 | AJ20: 6. Facile (Maîtrise rapide) | AK20: 6. D'accord (S'intègre facilement) | AL20: 6 | AM20: 6 | AN20: 7 | AO20: 6 | AP20: 2 | AQ20: 5. Très important | AR20: 5. Très important | AS20: 5. Très important | AT20: 5. Très important | AU20: 5 | AV20: 7 | AW20: 6. Approfondie (Parcours certifiant ou auto-formation technique longue) | AX20: 6 | AY20: 6 | AZ20: 3. Plutôt en désaccord (Je procède à une revue importante) | BA20: 6 | BB20: 6 | BC20: 6 | BD20: 6 | BE20: Oui | BF20: 6 | BG20: 6. D’accord | BH20: 6 | BI20: 46-55 | BJ20: Homme | BK20: Associé | BL20: Plus de 10 ans | BM20: Audit Financier, Expertise comptable | BN20: Cabinet international
A21: 46041.502 | B21: 5. Régulièrement (Plusieurs fois par semaine) | C21: Outils fournis/agréés par le cabinet (ex: Copilot sécurisé) | E21: Version entreprise | M21: Rédaction (rapports, synthèses, notes, mails), Reformulation ou traduction de documents, Recherche d'informations ou de points techniques, Revue d'estimations comptables (provisions, dépréciations), Préparation de données (format, structuration, harmonisation des valeurs) | N21: De manière RECOMMANDÉE (cabinet encourage, mais facultatif) | O21: 4. Utile | P21: 5. Très utile | Q21: 5. Très utile | R21: 2. Peu utile | S21: 4. Utile | T21: 4. Utile | U21: 1. Pas du tout utile | V21: 3. Neutre | W21: 4. Utile | X21: 4. Utile | Y21: 4. Utile | Z21: 2. Peu utile | AA21: 2. Peu utile | AB21: 2. Peu utile | AC21: 4. Utile | AD21: 3. Neutre | AE21: 2. Peu utile | AF21: 3. Neutre | AG21: 3. Neutre | AH21: 3. Neutre | AI21: 6 | AJ21: 6. Facile (Maîtrise rapide) | AK21: 6. D'accord (S'intègre facilement) | AL21: 6 | AM21: 5 | AN21: 7 | AO21: 6 | AP21: 6 | AQ21: 4. Important | AR21: 4. Important | AS21: 3. Moyennement important | AT21: 3. Moyennement important | AU21: 6 | AV21: 5 | AW21: 4. Moyenne (Environ une journée de formation cumulée) | AX21: 5 | AY21: 5 | AZ21: 5. Plutôt d'accord (Je vérifie uniquement les points clés) | BA21: 6 | BB21: 5 | BC21: 5 | BD21: 5 | BE21: Oui | BF21: 6 | BG21: 5. Plutôt d’accord | BH21: 6 | BI21: 18-25 | BJ21: Homme | BK21: Junior | BL21: Moins de 2 ans | BM21: Audit Financier | BN21: Cabinet international
A22: 46042.408 | B22: 4. Parfois (Environ une fois par semaine) | C22: Outils fournis/agréés par le cabinet (ex: Copilot sécurisé) | E22: Version entreprise | G22: Version grand public | M22: Rédaction (rapports, synthèses, notes, mails), Reformulation ou traduction de documents, Recherche d'informations ou de points techniques | N22: De manière VOLONTAIRE (vous avez choisi vous-même) | O22: 4. Utile | P22: 4. Utile | Q22: 4. Utile | R22: 4. Utile | S22: 3. Neutre | T22: 4. Utile | U22: 2. Peu utile | V22: 4. Utile | W22: 3. Neutre | X22: 3. Neutre | Y22: 4. Utile | Z22: 4. Utile | AA22: 4. Utile | AB22: 4. Utile | AC22: 3. Neutre | AD22: 4. Utile | AE22: 2. Peu utile | AF22: 4. Utile | AG22: 3. Neutre | AH22: 3. Neutre | AI22: 4 | AJ22: 4. Ni facile, ni difficile (Prise en main normale) | AK22: 2. En désaccord (Difficile à intégrer au métier) | AL22: 6 | AM22: 7 | AN22: 7 | AO22: 3 | AP22: 5 | AQ22: 5. Très important | AR22: 5. Très important | AS22: 4. Important | AT22: 3. Moyennement important | AU22: 6 | AV22: 7 | AW22: 6. Approfondie (Parcours certifiant ou auto-formation technique longue) | AX22: 5 | AY22: 5 | AZ22: 3. Plutôt en désaccord (Je procède à une revue importante) | BA22: 6 | BB22: 4 | BC22: 5 | BD22: 2 | BE22: Conditionné à la politique du cabinet | BF22: 6 | BG22: 4. Neutre | BH22: 5 | BI22: 26-35 | BJ22: Homme | BK22: Superviseur | BL22: 6 - 7 ans | BM22: Audit Financier | BN22: National et membre d'un réseau
A23: 46043.86 | B23: 5. Régulièrement (Plusieurs fois par semaine) | C23: Outils grand public (ex: ChatGPT, Gemini ) | F23: Version entreprise | M23: Rédaction (rapports, synthèses, notes, mails), Analyse de données et génération d'insights, Reformulation ou traduction de documents, Recherche d'informations ou de points techniques | N23: De manière RECOMMANDÉE (cabinet encourage, mais facultatif) | O23: 4. Utile | P23: 4. Utile | Q23: 5. Très utile | R23: 2. Peu utile | S23: 3. Neutre | T23: 3. Neutre | U23: 3. Neutre | V23: 2. Peu utile | W23: 2. Peu utile | X23: 5. Très utile | Y23: 5. Très utile | Z23: 5. Très utile | AA23: 5. Très utile | AB23: 3. Neutre | AC23: 3. Neutre | AD23: 3. Neutre | AE23: 3. Neutre | AF23: 3. Neutre | AG23: 2. Peu utile | AH23: 5. Très utile | AI23: 6 | AJ23: 7. Très facile (Instinctif / Sans aide) | AK23: 6. D'accord (S'intègre facilement) | AL23: 3 | AM23: 5 | AN23: 6 | AO23: 5 | AP23: 2 | AQ23: 4. Important | AR23: 5. Très important | AS23: 3. Moyennement important | AT23: 1. Pas du tout important | AU23: 1 | AV23: 7 | AW23: 6. Approfondie (Parcours certifiant ou auto-formation technique longue) | AX23: 5 | AY23: 4 | AZ23: 4. Neutre (Le niveau de vérification dépend de la complexité) | BA23: 5 | BB23: 6 | BC23: 5 | BD23: 3 | BE23: Oui | BF23: 6 | BG23: 4. Neutre | BH23: 4 | BI23: 26-35 | BJ23: Femme | BK23: Senior | BL23: 4 - 5 ans | BM23: Audit Financier, Audit Interne, Audit acquisition | BN23: Cabinet local
A24: 46047.149 | B24: 7. Très fréquemment (Plusieurs fois par jour) | C24: Usage mix des deux | F24: Version grand public | M24: Correction et mise en cohérence de documents, Rapprochement/Comparaison de documents, Détermination du seuil de signification, Évaluation du contrôle interne, Recherche d'informations ou de points techniques, Rédaction (rapports, synthèses, notes, mails), Préparation de données (format, structuration, harmonisation des valeurs), Automatisation et création de scripts (SQL, VBA), Reformulation ou traduction de documents | N24: De manière VOLONTAIRE (vous avez choisi vous-même) | O24: 3. Neutre | P24: 3. Neutre | Q24: 3. Neutre | R24: 2. Peu utile | S24: 3. Neutre | T24: 3. Neutre | U24: 3. Neutre | V24: 3. Neutre | W24: 1. Pas du tout utile | X24: 3. Neutre | Y24: 3. Neutre | Z24: 3. Neutre | AA24: 3. Neutre | AB24: 1. Pas du tout utile | AC24: 3. Neutre | AD24: 3. Neutre | AE24: 3. Neutre | AF24: 1. Pas du tout utile | AG24: 1. Pas du tout utile | AH24: 3. Neutre | AI24: 7 | AJ24: 6. Facile (Maîtrise rapide) | AK24: 7. Tout à fait d'accord (Automatisme quotidien) | AL24: 2 | AM24: 7 | AN24: 1 | AO24: 7 | AP24: 7 | AQ24: 3. Moyennement important | AR24: 3. Moyennement important | AS24: 1. Pas du tout important | AT24: 1. Pas du tout important | AU24: 7 | AV24: 7 | AW24: 4. Moyenne (Environ une journée de formation cumulée) | AX24: 7 | AY24: 7 | AZ24: 4. Neutre (Le niveau de vérification dépend de la complexité) | BA24: 4 | BB24: 7 | BC24: 7 | BD24: 1 | BE24: Non | BF24: 7 | BG24: 4. Neutre | BH24: 7 | BI24: 46-55 | BJ24: Homme | BK24: Manager | BL24: Plus de 10 ans | BM24: Audit Financier, Audit IT, Audit Interne | BN24: Cabinet international
A25: 46047.747 | B25: 3. Rarement (1 à 3 fois par mois) | C25: Usage mix des deux | E25: Version entreprise | F25: Version grand public | M25: Recherche d'informations ou de points techniques, Rédaction (rapports, synthèses, notes, mails) | N25: De manière VOLONTAIRE (vous avez choisi vous-même) | O25: 5. Très utile | P25: 2. Peu utile | Q25: 4. Utile | R25: 5. Très utile | S25: 4. Utile | T25: 4. Utile | U25: 1. Pas du tout utile | V25: 1. Pas du tout utile | W25: 1. Pas du tout utile | X25: 1. Pas du tout utile | Y25: 5. Très utile | Z25: 4. Utile | AA25: 4. Utile | AB25: 5. Très utile | AC25: 5. Très utile | AD25: 4. Utile | AE25: 2. Peu utile | AF25: 2. Peu utile | AG25: 2. Peu utile | AH25: 4. Utile | AI25: 5 | AJ25: 6. Facile (Maîtrise rapide) | AK25: 3. Plutôt en désaccord (Demande un effort conscient) | AL25: 3 | AM25: 7 | AN25: 7 | AO25: 7 | AP25: 7 | AQ25: 5. Très important | AR25: 5. Très important | AS25: 5. Très important | AT25: 5. Très important | AU25: 7 | AV25: 7 | AW25: 2. Très limitée (Quelques vidéos ou articles consultés) | AX25: 5 | AY25: 7 | AZ25: 2. En désaccord (Je contrôle la quasi-totalité des éléments) | BA25: 7 | BB25: 4 | BC25: 2 | BD25: 2 | BE25: Non | BF25: 1 | BG25: 4. Neutre | BH25: 1 | BI25: 26-35 | BJ25: Femme | BK25: Junior | BL25: 2 - 3 ans | BM25: Audit Financier | BN25: Cabinet régional
A26: 46049.81 | B26: 2. Très rarement (Moins d'une fois par mois) | C26: Outils grand public (ex: ChatGPT, Gemini ) | F26: Version grand public | M26: Rédaction (rapports, synthèses, notes, mails) | N26: De manière VOLONTAIRE (vous avez choisi vous-même) | O26: 3. Neutre | P26: 3. Neutre | Q26: 3. Neutre | R26: 2. Peu utile | S26: 2. Peu utile | T26: 3. Neutre | U26: 2. Peu utile | V26: 3. Neutre | W26: 2. Peu utile | X26: 2. Peu utile | Y26: 2. Peu utile | Z26: 2. Peu utile | AA26: 2. Peu utile | AB26: 2. Peu utile | AC26: 2. Peu utile | AD26: 2. Peu utile | AE26: 2. Peu utile | AF26: 2. Peu utile | AG26: 2. Peu utile | AH26: 2. Peu utile | AI26: 5 | AJ26: 5. Plutôt facile (Assez intuitif) | AK26: 5. Plutôt d'accord (S'intègre assez bien) | AL26: 5 | AM26: 6 | AN26: 6 | AO26: 5 | AP26: 5 | AQ26: 3. Moyennement important | AR26: 3. Moyennement important | AS26: 3. Moyennement important | AT26: 3. Moyennement important | AU26: 4 | AV26: 6 | AW26: 2. Très limitée (Quelques vidéos ou articles consultés) | AX26: 4 | AY26: 4 | AZ26: 4. Neutre (Le niveau de vérification dépend de la complexité) | BA26: 4 | BB26: 5 | BC26: 5 | BD26: 3 | BE26: Oui | BF26: 5 | BG26: 4. Neutre | BH26: 5 | BI26: 26-35 | BJ26: Homme | BK26: Senior | BL26: 4 - 5 ans | BM26: Audit Financier | BN26: Cabinet international
A27: 46050.55 | B27: 7. Très fréquemment (Plusieurs fois par jour) | C27: Outils fournis/agréés par le cabinet (ex: Copilot sécurisé) | K27: Version entreprise | M27: Automatisation et création de scripts (SQL, VBA), Rédaction (rapports, synthèses, notes, mails), Reformulation ou traduction de documents, Correction et mise en cohérence de documents, Rapprochement/Comparaison de documents | N27: De manière RECOMMANDÉE (cabinet encourage, mais facultatif) | O27: 5. Très utile | P27: 5. Très utile | Q27: 5. Très utile | R27: 5. Très utile | S27: 5. Très utile | T27: 1. Pas du tout utile | U27: 1. Pas du tout utile | V27: 1. Pas du tout utile | W27: 1. Pas du tout utile | X27: 4. Utile | Y27: 5. Très utile | Z27: 5. Très utile | AA27: 5. Très utile | AB27: 5. Très utile | AC27: 5. Très utile | AD27: 1. Pas du tout utile | AE27: 1. Pas du tout utile | AF27: 1. Pas du tout utile | AG27: 1. Pas du tout utile | AH27: 5. Très utile | AI27: 6 | AJ27: 5. Plutôt facile (Assez intuitif) | AK27: 6. D'accord (S'intègre facilement) | AL27: 2 | AM27: 2 | AN27: 3 | AO27: 3 | AP27: 6 | AQ27: 3. Moyennement important | AR27: 2. Peu important | AS27: 3. Moyennement important | AT27: 4. Important | AU27: 4 | AV27: 7 | AW27: 2. Très limitée (Quelques vidéos ou articles consultés) | AX27: 6 | AY27: 5 | AZ27: 2. En désaccord (Je contrôle la quasi-totalité des éléments) | BA27: 6 | BB27: 7 | BC27: 7 | BD27: 6 | BE27: Oui | BF27: 4 | BG27: 4. Neutre | BH27: 7 | BI27: 18-25 | BJ27: Femme | BK27: Junior | BL27: Moins de 2 ans | BM27: Audit Financier | BN27: Cabinet international
A28: 46050.558 | B28: 5. Régulièrement (Plusieurs fois par semaine) | C28: Outils fournis/agréés par le cabinet (ex: Copilot sécurisé) | E28: Version entreprise | F28: Version grand public | M28: Rapprochement/Comparaison de documents, Aide à la décision, Recherche d'informations ou de points techniques, Évaluation du contrôle interne, Rédaction (rapports, synthèses, notes, mails), Automatisation et création de scripts (SQL, VBA), Analyse de données et génération d'insights | N28: De manière VOLONTAIRE (vous avez choisi vous-même) | O28: 3. Neutre | P28: 3. Neutre | Q28: 3. Neutre | R28: 3. Neutre | S28: 3. Neutre | T28: 3. Neutre | U28: 3. Neutre | V28: 3. Neutre | W28: 3. Neutre | X28: 3. Neutre | Y28: 3. Neutre | Z28: 4. Utile | AA28: 4. Utile | AB28: 4. Utile | AC28: 4. Utile | AD28: 3. Neutre | AE28: 3. Neutre | AF28: 3. Neutre | AG28: 4. Utile | AH28: 3. Neutre | AI28: 6 | AJ28: 5. Plutôt facile (Assez intuitif) | AK28: 6. D'accord (S'intègre facilement) | AL28: 3 | AM28: 5 | AN28: 6 | AO28: 6 | AP28: 4 | AQ28: 4. Important | AR28: 4. Important | AS28: 3. Moyennement important | AT28: 4. Important | AU28: 6 | AV28: 6 | AW28: 2. Très limitée (Quelques vidéos ou articles consultés) | AX28: 6 | AY28: 3 | AZ28: 2. En désaccord (Je contrôle la quasi-totalité des éléments) | BA28: 6 | BB28: 3 | BC28: 5 | BD28: 2 | BE28: Non | BF28: 2 | BG28: 4. Neutre | BH28: 5 | BI28: 18-25 | BJ28: Femme | BK28: Junior | BL28: Moins de 2 ans | BM28: Audit IT | BN28: Cabinet international | BO28: L’IA générative offre un fort potentiel pour gagner du temps et stimuler la créativité, mais elle doit être utilisée avec discernement pour garantir la fiabilité et préserver la confidentialité.
A29: 46050.558 | B29: 7. Très fréquemment (Plusieurs fois par jour) | C29: Outils fournis/agréés par le cabinet (ex: Copilot sécurisé) | E29: Version entreprise | M29: Préparation de données (format, structuration, harmonisation des valeurs), Aide à la décision, Automatisation et création de scripts (SQL, VBA), Reformulation ou traduction de documents | N29: De manière VOLONTAIRE (vous avez choisi vous-même) | O29: 4. Utile | P29: 4. Utile | Q29: 4. Utile | R29: 3. Neutre | S29: 5. Très utile | T29: 3. Neutre | U29: 2. Peu utile | V29: 2. Peu utile | W29: 3. Neutre | X29: 5. Très utile | Y29: 4. Utile | Z29: 4. Utile | AA29: 4. Utile | AB29: 3. Neutre | AC29: 5. Très utile | AD29: 3. Neutre | AE29: 2. Peu utile | AF29: 2. Peu utile | AG29: 3. Neutre | AH29: 5. Très utile | AI29: 5 | AJ29: 6. Facile (Maîtrise rapide) | AK29: 7. Tout à fait d'accord (Automatisme quotidien) | AL29: 4 | AM29: 7 | AN29: 7 | AO29: 2 | AP29: 7 | AQ29: 5. Très important | AR29: 2. Peu important | AS29: 2. Peu important | AT29: 4. Important | AU29: 2 | AV29: 4 | AW29: 5. Solide (Plusieurs jours de formation ou modules suivis) | AX29: 6 | AY29: 6 | AZ29: 3. Plutôt en désaccord (Je procède à une revue importante) | BA29: 5 | BB29: 5 | BC29: 5 | BD29: 5 | BE29: Oui | BF29: 2 | BG29: 4. Neutre | BH29: 5 | BI29: 18-25 | BJ29: Homme | BK29: Senior | BL29: 4 - 5 ans | BM29: Audit IT | BN29: Cabinet international | BO29: C'est top mais il est essentiel de conserver son sens critique et ne pas suivre bêtement les réponses de l'IA. Le risque est de perdre en questionnement, perdre en raisonnement, perdre en intelligence.
A30: 46051.57 | B30: 5. Régulièrement (Plusieurs fois par semaine) | C30: Outils fournis/agréés par le cabinet (ex: Copilot sécurisé) | E30: Version entreprise | K30: Version entreprise | L30: Version entreprise | M30: Aide à la décision, Analyse de données et génération d'insights, Rédaction (rapports, synthèses, notes, mails), Reformulation ou traduction de documents, Recherche d'informations ou de points techniques, Rapprochement/Comparaison de documents, Automatisation et création de scripts (SQL, VBA) | N30: De manière RECOMMANDÉE (cabinet encourage, mais facultatif) | O30: 5. Très utile | P30: 4. Utile | Q30: 3. Neutre | R30: 4. Utile | S30: 5. Très utile | T30: 3. Neutre | U30: 1. Pas du tout utile | V30: 2. Peu utile | W30: 4. Utile | X30: 4. Utile | Y30: 4. Utile | Z30: 5. Très utile | AA30: 5. Très utile | AB30: 3. Neutre | AC30: 5. Très utile | AD30: 4. Utile | AE30: 1. Pas du tout utile | AF30: 1. Pas du tout utile | AG30: 4. Utile | AH30: 4. Utile | AI30: 5 | AJ30: 3. Plutôt difficile (Peu intuitif) | AK30: 5. Plutôt d'accord (S'intègre assez bien) | AL30: 6 | AM30: 6 | AN30: 3 | AO30: 3 | AP30: 6 | AQ30: 5. Très important | AR30: 4. Important | AS30: 3. Moyennement important | AT30: 3. Moyennement important | AU30: 5 | AV30: 6 | AW30: 6. Approfondie (Parcours certifiant ou auto-formation technique longue) | AX30: 5 | AY30: 5 | AZ30: 2. En désaccord (Je contrôle la quasi-totalité des éléments) | BA30: 6 | BB30: 6 | BC30: 6 | BD30: 3 | BE30: Oui | BF30: 5 | BG30: 4. Neutre | BH30: 5 | BI30: 36-45 | BJ30: Homme | BK30: Manager | BL30: Plus de 10 ans | BM30: Audit Financier | BN30: Cabinet international
A31: 46052.59 | B31: 2. Très rarement (Moins d'une fois par mois) | C31: Usage mix des deux | E31: Version entreprise | M31: Rédaction (rapports, synthèses, notes, mails), Préparation de données (format, structuration, harmonisation des valeurs) | N31: De manière VOLONTAIRE (vous avez choisi vous-même) | O31: 4. Utile | P31: 4. Utile | Q31: 4. Utile | R31: 4. Utile | S31: 4. Utile | T31: 4. Utile | U31: 4. Utile | V31: 4. Utile | W31: 4. Utile | X31: 4. Utile | Y31: 4. Utile | Z31: 4. Utile | AA31: 4. Utile | AB31: 4. Utile | AC31: 4. Utile | AD31: 4. Utile | AE31: 4. Utile | AF31: 4. Utile | AG31: 3. Neutre | AH31: 3. Neutre | AI31: 6 | AJ31: 6. Facile (Maîtrise rapide) | AK31: 6. D'accord (S'intègre facilement) | AL31: 4 | AM31: 4 | AN31: 5 | AO31: 4 | AP31: 5 | AQ31: 3. Moyennement important | AR31: 3. Moyennement important | AS31: 3. Moyennement important | AT31: 4. Important | AU31: 5 | AV31: 5 | AW31: 5. Solide (Plusieurs jours de formation ou modules suivis) | AX31: 5 | AY31: 4 | AZ31: 4. Neutre (Le niveau de vérification dépend de la complexité) | BA31: 5 | BB31: 5 | BC31: 4 | BD31: 5 | BE31: Oui | BF31: 5 | BG31: 4. Neutre | BH31: 5 | BI31: 18-25 | BJ31: Homme | BK31: Junior | BL31: Moins de 2 ans | BM31: Audit Financier | BN31: Cabinet régional
A32: 46052.591 | B32: 2. Très rarement (Moins d'une fois par mois) | C32: Outils fournis/agréés par le cabinet (ex: Copilot sécurisé) | D32: Version entreprise | E32: Version entreprise | K32: Version entreprise | M32: Correction et mise en cohérence de documents, Recherche d'informations ou de points techniques, Automatisation et création de scripts (SQL, VBA) | N32: De manière VOLONTAIRE (vous avez choisi vous-même) | O32: 3. Neutre | P32: 4. Utile | Q32: 4. Utile | R32: 4. Utile | S32: 4. Utile | T32: 2. Peu utile | U32: 2. Peu utile | V32: 2. Peu utile | W32: 2. Peu utile | X32: 3. Neutre | Y32: 3. Neutre | Z32: 3. Neutre | AA32: 3. Neutre | AB32: 3. Neutre | AC32: 3. Neutre | AD32: 1. Pas du tout utile | AE32: 1. Pas du tout utile | AF32: 1. Pas du tout utile | AG32: 1. Pas du tout utile | AH32: 1. Pas du tout utile | AI32: 5 | AJ32: 3. Plutôt difficile (Peu intuitif) | AK32: 5. Plutôt d'accord (S'intègre assez bien) | AL32: 7 | AM32: 7 | AN32: 7 | AO32: 5 | AP32: 7 | AQ32: 5. Très important | AR32: 5. Très important | AS32: 3. Moyennement important | AT32: 3. Moyennement important | AU32: 5 | AV32: 5 | AW32: 3. Faible (Moins de 5 heures de formation au total) | AX32: 6 | AY32: 5 | AZ32: 3. Plutôt en désaccord (Je procède à une revue importante) | BA32: 7 | BB32: 4 | BC32: 3 | BD32: 2 | BE32: Non | BF32: 7 | BG32: 4. Neutre | BH32: 5 | BI32: 18-25 | BJ32: Homme | BK32: Junior | BL32: Moins de 2 ans | BM32: Audit Financier, Audit RSE | BN32: Cabinet international
